<!DOCTYPE html>
<html lang="en">

<head>
  <title>Async Await</title>
</head>

<body>
  <script>
    function breathe(amount) {
      return new Promise((resolve, reject) => {
        if (amount < 500) {
          reject('That is too small of a value');
        }
        setTimeout(() => resolve(`Done for ${amount} ms`), amount);
      });
    }

    function catchErrors( fn, ErrorHandleFn = (err => console.error(err)) ) {
      return function (...args) {
        console.log(...args); //这里的 ...args 就是 wrappedFunction 的参数
        return fn(...args).catch(ErrorHandleFn);
      }
    }

    async function go(name, last) {
      console.log(`Starting for ${name} ${last}!`);
      const res = await breathe(1000);
      console.log(res);
      const res2 = await breathe(300);
      console.log(res2);
      const res3 = await breathe(750);
      console.log(res3);
      const res4 = await breathe(900);
      console.log(res4);
      console.log('end');
    }
    const wrappedFunction = catchErrors(go, err => console.error(err));
    wrappedFunction('Wes', 'Bos');

    const test = go('Wes', 'Bos');
    console.log(test, '捕获异常原理：调用async函数，其返回值是一个Promise，这就为.catch捕获异常提供了条件');
  </script>
</body>

</html>
